<?xml version="1.0" encoding="utf-8"?>

<robot name="solo_full" xmlns:controller="http://playerstage.sourceforge.net/gazebo/xmlschema/#controller" xmlns:interface="http://playerstage.sourceforge.net/gazebo/xmlschema/#interface" xmlns:sensor="http://playerstage.sourceforge.net/gazebo/xmlschema/#sensor">
	<!-- This file is based on: https://atlas.is.localnet/confluence/display/AMDW/Quadruped+URDF+Files -->

  <material name="grey">
    <color rgba="0.8 0.8 0.8 1.0"/>
  </material>

  <link name="base">
    <inertial>
      <origin rpy="0 0 0" xyz="0 0 0"/>
      <mass value="1.43315091"/>
      <inertia ixx="0.00578574" ixy="0.0" ixz="0.0" iyy="0.01938108" iyz="0.0" izz="0.02476124"/>
    </inertial>
    <visual>
      <origin rpy="0 0 0" xyz="0 0 0"/>
      <geometry>
        <mesh filename="package://meshes/stl/with_foot/solo_body.stl"/>
      </geometry>
      <material name="grey"/>
    </visual>
    <collision>
      <origin rpy="0 0 0" xyz="0 0 0"/>
      <geometry>
        <mesh filename="package://meshes/stl/with_foot/solo_body.stl"/>
      </geometry>
      <material name="grey"/>
    </collision>
    <contact>
      <lateral_friction value="1.0"/>
      <restitution value="0.5"/>
    </contact>
  </link>

  <joint name="fl_hip" type="revolute">
    <parent link="base"/>
    <child link="fl_upper_leg"/>
    <limit effort="2.7" lower="-3.141593" upper="3.141593" velocity="1.0"/>
    <axis xyz="0 1 0"/>
    <origin rpy="0 0 0" xyz="0.19 0.1046 0"/>
    <dynamics damping="0.0" friction="0.0"/>
  </joint>

  <link name="fl_upper_leg">
    <inertial>
      <origin rpy="0 0 0" xyz="0.00001377 0.01935853 -0.07870700"/>
      <mass value="0.14853845"/>
      <inertia ixx="0.00041107" ixy="0.0" ixz="0.0" iyy="0.00041193" iyz="0.00004671" izz="0.00003024"/>
    </inertial>
    <visual>
      <origin rpy="0 0 0" xyz="0 0 0"/>
      <geometry>
        <mesh filename="package://meshes/stl/with_foot/solo_upper_leg_left_side.stl"/>
      </geometry>
      <material name="grey"/>
    </visual>
    <collision>
      <origin rpy="0 0 0" xyz="0 0 0"/>
      <geometry>
        <mesh filename="package://meshes/stl/with_foot/solo_upper_leg_left_side.stl"/>
      </geometry>
      <material name="grey"/>
    </collision>
    <contact>
      <lateral_friction value="1.0"/>
      <restitution value="0.5"/>
    </contact>
  </link>

  <joint name="fl_knee" type="revolute">
    <parent link="fl_upper_leg"/>
    <child link="fl_lower_leg"/>
    <limit effort="2.7" lower="-3.141593" upper="3.141593" velocity="1.0"/>
    <axis xyz="0 1 0"/>
    <origin rpy="0 0 0" xyz="0 0.03745 -0.16"/>
    <dynamics damping="0.0" friction="0.0"/>
  </joint>

  <link name="fl_lower_leg">
    <inertial>
      <origin rpy="0 0 0" xyz="0.0 0.00787644 -0.08928215"/>
      <mass value="0.03070001"/>
      <inertia ixx="0.00012024" ixy="0.0" ixz="0.0" iyy="0.00012029" iyz="0.00000305" izz="0.00000216"/>
    </inertial>
    <visual>
      <origin rpy="0 0 0" xyz="0 0 0"/>
      <geometry>
        <mesh filename="package://meshes/stl/with_foot/solo_lower_leg_left_side.stl"/>
      </geometry>
      <material name="grey"/>
    </visual>
    <collision>
      <origin rpy="0 0 0" xyz="0 0 0"/>
      <geometry>
        <mesh filename="package://meshes/stl/with_foot/solo_lower_leg_left_side.stl"/>
      </geometry>
      <material name="grey"/>
    </collision>
    <contact>
      <lateral_friction value="1.0"/>
      <restitution value="0.5"/>
    </contact>
  </link>

  <joint name="fl_ankle" type="fixed">
    <parent link="fl_lower_leg"/>
    <child link="fl_foot"/>
    <origin rpy="0 0 0" xyz="0 0.008 -0.16"/>
    <limit effort="2.7" lower="-3.141593" upper="3.141593" velocity="1.0"/>
    <dynamics damping="0.0" friction="0.0"/>
  </joint>

  <link name="fl_foot">
    <inertial>
      <origin rpy="0 0 0" xyz="0 0 0.00035767"/>
      <mass value="0.00693606"/>
      <inertia ixx="0.00000057" ixy="0.0" ixz="0.0" iyy="0.00000084" iyz="0.0" izz="0.00000053"/>
    </inertial>
    <visual>
      <origin rpy="0 0 0" xyz="0 0 0"/>
      <geometry>
        <mesh filename="package://meshes/stl/with_foot/solo_foot.stl"/>
      </geometry>
      <material name="grey"/>
    </visual>
    <collision>
      <origin rpy="0 0 0" xyz="0 0 0"/>
      <geometry>
        <mesh filename="package://meshes/stl/with_foot/solo_foot.stl"/>
      </geometry>
      <material name="grey"/>
    </collision>
    <contact>
      <lateral_friction value="1.0"/>
      <restitution value="0.5"/>
    </contact>
  </link>

  <joint name="fr_hip" type="revolute">
    <parent link="base"/>
    <child link="fr_upper_leg"/>
    <limit effort="2.7" lower="-3.141593" upper="3.141593" velocity="1.0"/>
    <axis xyz="0 1 0"/>
    <origin rpy="0 0 0" xyz="0.19 -0.1046 0"/>
    <dynamics damping="0.0" friction="0.0"/>
  </joint>

  <link name="fr_upper_leg">
    <inertial>
      <origin rpy="0 0 0" xyz="-0.00001377 -0.01935853 -0.07870700"/>
      <mass value="0.14853845"/>
      <inertia ixx="0.00041107" ixy="0.0" ixz="0.0" iyy="0.00041193" iyz="-0.00004671" izz="0.00003024"/>
    </inertial>
    <visual>
      <origin rpy="0 0 0" xyz="0 0 0"/>
      <geometry>
        <mesh filename="package://meshes/stl/with_foot/solo_upper_leg_right_side.stl"/>
      </geometry>
      <material name="grey"/>
    </visual>
    <collision>
      <origin rpy="0 0 0" xyz="0 0 0"/>
      <geometry>
        <mesh filename="package://meshes/stl/with_foot/solo_upper_leg_right_side.stl"/>
      </geometry>
      <material name="grey"/>
    </collision>
    <contact>
      <lateral_friction value="1.0"/>
      <restitution value="0.5"/>
    </contact>
  </link>

  <joint name="fr_knee" type="revolute">
    <parent link="fr_upper_leg"/>
    <child link="fr_lower_leg"/>
    <limit effort="2.7" lower="-3.141593" upper="3.141593" velocity="1.0"/>
    <axis xyz="0 1 0"/>
    <origin rpy="0 0 0" xyz="0 -0.03745 -0.16"/>
    <dynamics damping="0.0" friction="0.0"/>
  </joint>

  <link name="fr_lower_leg">
    <inertial>
      <origin rpy="0 0 0" xyz="0.0 0.00787644 -0.08928215"/>
      <mass value="0.03070001"/>
      <inertia ixx="0.00012024" ixy="0.0" ixz="0.0" iyy="0.00012029" iyz="-0.00000305" izz="0.00000216"/>
    </inertial>
    <visual>
      <origin rpy="0 0 0" xyz="0 0 0"/>
      <geometry>
        <mesh filename="package://meshes/stl/with_foot/solo_lower_leg_right_side.stl"/>
      </geometry>
      <material name="grey"/>
    </visual>
    <collision>
      <origin rpy="0 0 0" xyz="0 0 0"/>
      <geometry>
        <mesh filename="package://meshes/stl/with_foot/solo_lower_leg_right_side.stl"/>
      </geometry>
      <material name="grey"/>
    </collision>
    <contact>
      <lateral_friction value="1.0"/>
      <restitution value="0.5"/>
    </contact>
  </link>

  <joint name="fr_ankle" type="fixed">
    <parent link="fr_lower_leg"/>
    <child link="fr_foot"/>
    <origin rpy="0 0 0" xyz="0 -0.008 -0.16"/>
    <limit effort="2.7" lower="-3.141593" upper="3.141593" velocity="1.0"/>
    <dynamics damping="0.0" friction="0.0"/>
  </joint>

  <link name="fr_foot">
    <inertial>
      <origin rpy="0 0 0" xyz="0 0 0.00035767"/>
      <mass value="0.00693606"/>
      <inertia ixx="0.00000057" ixy="0.0" ixz="0.0" iyy="0.00000084" iyz="0.0" izz="0.00000053"/>
    </inertial>
    <visual>
      <origin rpy="0 0 0" xyz="0 0 0"/>
      <geometry>
        <mesh filename="package://meshes/stl/with_foot/solo_foot.stl"/>
      </geometry>
      <material name="grey"/>
    </visual>
    <collision>
      <origin rpy="0 0 0" xyz="0 0 0"/>
      <geometry>
        <mesh filename="package://meshes/stl/with_foot/solo_foot.stl"/>
      </geometry>
      <material name="grey"/>
    </collision>
    <contact>
      <lateral_friction value="1.0"/>
      <restitution value="0.5"/>
    </contact>
  </link>

  <joint name="bl_hip" type="revolute">
    <parent link="base"/>
    <child link="bl_upper_leg"/>
    <limit effort="2.7" lower="-3.141593" upper="3.141593" velocity="1.0"/>
    <axis xyz="0 1 0"/>
    <origin rpy="0 0 0" xyz="-0.19 0.1046 0"/>
    <dynamics damping="0.0" friction="0.0"/>
  </joint>

  <link name="bl_upper_leg">
    <inertial>
      <origin rpy="0 0 0" xyz="0.00001377 0.01935853 -0.07870700"/>
      <mass value="0.14853845"/>
      <inertia ixx="0.00041107" ixy="0.0" ixz="0.0" iyy="0.00041193" iyz="0.00004671" izz="0.00003024"/>
    </inertial>
    <visual>
      <origin rpy="0 0 0" xyz="0 0 0"/>
      <geometry>
        <mesh filename="package://meshes/stl/with_foot/solo_upper_leg_left_side.stl"/>
      </geometry>
      <material name="grey"/>
    </visual>
    <collision>
      <origin rpy="0 0 0" xyz="0 0 0"/>
      <geometry>
        <mesh filename="package://meshes/stl/with_foot/solo_upper_leg_left_side.stl"/>
      </geometry>
      <material name="grey"/>
    </collision>
    <contact>
      <lateral_friction value="1.0"/>
      <restitution value="0.5"/>
    </contact>
  </link>

  <joint name="bl_knee" type="revolute">
    <parent link="bl_upper_leg"/>
    <child link="bl_lower_leg"/>
    <limit effort="2.7" lower="-3.141593" upper="3.141593" velocity="1.0"/>
    <axis xyz="0 1 0"/>
    <origin rpy="0 0 0" xyz="0 0.03745 -0.16"/>
    <dynamics damping="0.0" friction="0.0"/>
  </joint>

  <link name="bl_lower_leg">
    <inertial>
      <origin rpy="0 0 0" xyz="0.0 0.00787644 -0.08928215"/>
      <mass value="0.03070001"/>
      <inertia ixx="0.00012024" ixy="0.0" ixz="0.0" iyy="0.00012029" iyz="0.00000305" izz="0.00000216"/>
    </inertial>
    <visual>
      <origin rpy="0 0 0" xyz="0 0 0"/>
      <geometry>
        <mesh filename="package://meshes/stl/with_foot/solo_lower_leg_left_side.stl"/>
      </geometry>
      <material name="grey"/>
    </visual>
    <collision>
      <origin rpy="0 0 0" xyz="0 0 0"/>
      <geometry>
        <mesh filename="package://meshes/stl/with_foot/solo_lower_leg_left_side.stl"/>
      </geometry>
      <material name="grey"/>
    </collision>
    <contact>
      <lateral_friction value="1.0"/>
      <restitution value="0.5"/>
    </contact>
  </link>

  <joint name="bl_ankle" type="fixed">
    <parent link="bl_lower_leg"/>
    <child link="bl_foot"/>
    <origin rpy="0 0 0" xyz="0 0.008 -0.16"/>
    <limit effort="2.7" lower="-3.141593" upper="3.141593" velocity="1.0"/>
    <dynamics damping="0.0" friction="0.0"/>
  </joint>

  <link name="bl_foot">
    <inertial>
      <origin rpy="0 0 0" xyz="0 0 0.00035767"/>
      <mass value="0.00693606"/>
      <inertia ixx="0.00000057" ixy="0.0" ixz="0.0" iyy="0.00000084" iyz="0.0" izz="0.00000053"/>
    </inertial>
    <visual>
      <origin rpy="0 0 0" xyz="0 0 0"/>
      <geometry>
        <mesh filename="package://meshes/stl/with_foot/solo_foot.stl"/>
      </geometry>
      <material name="grey"/>
    </visual>
    <collision>
      <origin rpy="0 0 0" xyz="0 0 0"/>
      <geometry>
        <mesh filename="package://meshes/stl/with_foot/solo_foot.stl"/>
      </geometry>
      <material name="grey"/>
    </collision>
    <contact>
      <lateral_friction value="1.0"/>
      <restitution value="0.5"/>
    </contact>
  </link>

  <joint name="br_hip" type="revolute">
    <parent link="base"/>
    <child link="br_upper_leg"/>
    <limit effort="2.7" lower="-3.141593" upper="3.141593" velocity="1.0"/>
    <axis xyz="0 1 0"/>
    <origin rpy="0 0 0" xyz="-0.19 -0.1046 0"/>
    <dynamics damping="0.0" friction="0.0"/>
  </joint>

  <link name="br_upper_leg">
    <inertial>
      <origin rpy="0 0 0" xyz="-0.00001377 -0.01935853 -0.07870700"/>
      <mass value="0.14853845"/>
      <inertia ixx="0.00041107" ixy="0.0" ixz="0.0" iyy="0.00041193" iyz="-0.00004671" izz="0.00003024"/>
    </inertial>
    <visual>
      <origin rpy="0 0 0" xyz="0 0 0"/>
      <geometry>
        <mesh filename="package://meshes/stl/with_foot/solo_upper_leg_right_side.stl"/>
      </geometry>
      <material name="grey"/>
    </visual>
    <collision>
      <origin rpy="0 0 0" xyz="0 0 0"/>
      <geometry>
        <mesh filename="package://meshes/stl/with_foot/solo_upper_leg_right_side.stl"/>
      </geometry>
      <material name="grey"/>
    </collision>
    <contact>
      <lateral_friction value="1.0"/>
      <restitution value="0.5"/>
    </contact>
  </link>

  <joint name="br_knee" type="revolute">
    <parent link="br_upper_leg"/>
    <child link="br_lower_leg"/>
    <limit effort="2.7" lower="-3.141593" upper="3.141593" velocity="1.0"/>
    <axis xyz="0 1 0"/>
    <origin rpy="0 0 0" xyz="0 -0.03745 -0.16"/>
    <dynamics damping="0.0" friction="0.0"/>
  </joint>

  <link name="br_lower_leg">
    <inertial>
      <origin rpy="0 0 0" xyz="0.0 0.00787644 -0.08928215"/>
      <mass value="0.03070001"/>
      <inertia ixx="0.00012024" ixy="0.0" ixz="0.0" iyy="0.00012029" iyz="-0.00000305" izz="0.00000216"/>
    </inertial>
    <visual>
      <origin rpy="0 0 0" xyz="0 0 0"/>
      <geometry>
        <mesh filename="package://meshes/stl/with_foot/solo_lower_leg_right_side.stl"/>
      </geometry>
      <material name="grey"/>
    </visual>
    <collision>
      <origin rpy="0 0 0" xyz="0 0 0"/>
      <geometry>
        <mesh filename="package://meshes/stl/with_foot/solo_lower_leg_right_side.stl"/>
      </geometry>
      <material name="grey"/>
    </collision>
    <contact>
      <lateral_friction value="1.0"/>
      <restitution value="0.5"/>
    </contact>
  </link>

  <joint name="br_ankle" type="fixed">
    <parent link="br_lower_leg"/>
    <child link="br_foot"/>
    <origin rpy="0 0 0" xyz="0 -0.008 -0.16"/>
    <limit effort="2.7" lower="-3.141593" upper="3.141593" velocity="1.0"/>
    <dynamics damping="0.0" friction="0.0"/>
  </joint>

  <link name="br_foot">
    <inertial>
      <origin rpy="0 0 0" xyz="0 0 0.00035767"/>
      <mass value="0.00693606"/>
      <inertia ixx="0.00000057" ixy="0.0" ixz="0.0" iyy="0.00000084" iyz="0.0" izz="0.00000053"/>
    </inertial>
    <visual>
      <origin rpy="0 0 0" xyz="0 0 0"/>
      <geometry>
        <mesh filename="package://meshes/stl/with_foot/solo_foot.stl"/>
      </geometry>
      <material name="grey"/>
    </visual>
    <collision>
      <origin rpy="0 0 0" xyz="0 0 0"/>
      <geometry>
        <mesh filename="package://meshes/stl/with_foot/solo_foot.stl"/>
      </geometry>
      <material name="grey"/>
    </collision>
    <contact>
      <lateral_friction value="1.0"/>
      <restitution value="0.5"/>
    </contact>
  </link>

</robot>
